Workbook

Sheet Planilha1
A1: Time | B1: pwind
A2: 0.95833333 | B2: =Plot!B3 -> 24.228
A3: 0.96875 | B3: =B2+(($B$6-B2)/($A$6-A2)*(A2-A3)) -> 24.230576
A4: 0.97916667 | B4: =B3+(($B$6-B3)/($A$6-A3)*(A3-A4)) -> 24.233097
A5: 0.98958333 | B5: =B4+(($B$6-B4)/($A$6-A4)*(A4-A5)) -> 24.235564
A6: 0 | B6: =Plot!C3 -> 24.465
A7: 0.010416667 | B7: =B6+(($B$10-B6)/($A$10-A6)*(A7-A6)) -> 24.39025
A8: 0.020833333 | B8: =B7+(($B$10-B7)/($A$10-A7)*(A8-A7)) -> 24.3155
A9: 0.03125 | B9: =B8+(($B$10-B8)/($A$10-A8)*(A9-A8)) -> 24.24075
A10: 0.041666667 | B10: =Plot!D3 -> 24.166
A11: 0.052083333 | B11: =B10+((B10-$B$14)/(A10-$A$14))*(A11-A10) -> 24.18375
A12: 0.0625 | B12: =B11+((B11-$B$14)/(A11-$A$14))*(A12-A11) -> 24.2015
A13: 0.072916667 | B13: =B12+((B12-$B$14)/(A12-$A$14))*(A13-A12) -> 24.21925
A14: 2:00 | B14: =Plot!E3 -> 24.237
A15: 0.09375 | B15: =B14+((B14-$B$18)/(A14-$A$18))*(A15-A14) -> 24.21925
A16: 0.10416667 | B16: =B15+((B15-$B$18)/(A15-$A$18))*(A16-A15) -> 24.2015
A17: 0.11458333 | B17: =B16+((B16-$B$18)/(A16-$A$18))*(A17-A16) -> 24.18375
A18: 0.125 | B18: =Plot!F3 -> 24.166
A19: 0.13541667 | B19: =B18+((B18-$B$22)/(A18-$A$22))*(A19-A18) -> 24.166
A20: 0.14583333 | B20: =B19+((B19-$B$22)/(A19-$A$22))*(A20-A19) -> 24.166
A21: 0.15625 | B21: =B20+((B20-$B$22)/(A20-$A$22))*(A21-A20) -> 24.166
A22: 4:00 | B22: =Plot!G3 -> 24.166
A23: 0.17708333 | B23: =B22+((B22-$B$26)/(A22-$A$26))*(A23-A22) -> 24.166
A24: 0.1875 | B24: =B23+((B23-$B$26)/(A23-$A$26))*(A24-A23) -> 24.166
A25: 0.19791667 | B25: =B24+((B24-$B$26)/(A24-$A$26))*(A25-A24) -> 24.166
A26: 5:00 | B26: =Plot!H3 -> 24.166
A27: 0.21875 | B27: =B26+((B26-$B$30)/(A26-$A$30))*(A27-A26) -> 24.166
A28: 0.22916667 | B28: =B27+((B27-$B$30)/(A27-$A$30))*(A28-A27) -> 24.166
A29: 0.23958333 | B29: =B28+((B28-$B$30)/(A28-$A$30))*(A29-A28) -> 24.166
A30: 6:00 | B30: =Plot!I3 -> 24.166
A31: 0.26041667 | B31: =B30+((B30-$B$34)/(A30-$A$34))*(A31-A30) -> 24.1785
A32: 0.27083333 | B32: =B31+((B31-$B$34)/(A31-$A$34))*(A32-A31) -> 24.191
A33: 0.28125 | B33: =B32+((B32-$B$34)/(A32-$A$34))*(A33-A32) -> 24.2035
A34: 7:00 | B34: =Plot!J3 -> 24.216
A35: 0.30208333 | B35: =B34+((B34-$B$38)/(A34-$A$38))*(A35-A34) -> 24.2445
A36: 0.3125 | B36: =B35+((B35-$B$38)/(A35-$A$38))*(A36-A35) -> 24.273
A37: 0.32291667 | B37: =B36+((B36-$B$38)/(A36-$A$38))*(A37-A36) -> 24.3015
A38: 8:00 | B38: =Plot!K3 -> 24.33
A39: 0.34375 | B39: =B38+((B38-$B$42)/(A38-$A$42))*(A39-A38) -> 24.42675
A40: 0.35416667 | B40: =B39+((B39-$B$42)/(A39-$A$42))*(A40-A39) -> 24.5235
...

Sheet Plot
B2: 23:00 | C2: 0:00 | D2: 1:00 | E2: 2:00 | F2: 3:00 | G2: 4:00 | H2: 5:00 | I2: 6:00 | J2: 7:00 | K2: 8:00 | L2: 9:00 | M2: 10:00 | N2: 11:00 | O2: 12:00 | P2: 13:00 | Q2: 14:00 | R2: 15:00 | S2: 16:00 | T2: 17:00 | U2: 18:00 | V2: 19:00 | W2: 20:00 | X2: 21:00 | Y2: 22:00
A3: Embuaça | B3: 24.228 | C3: 24.465 | D3: 24.166 | E3: 24.237 | F3: 24.166 | G3: 24.166 | H3: 24.166 | I3: 24.166 | J3: 24.216 | K3: 24.33 | L3: 24.717 | M3: 25.037 | N3: 24.99 | O3: 26.702 | P3: 26.222 | Q3: 26.914 | R3: 26.996 | S3: 26.505 | T3: 25.807 | U3: 24.455 | V3: 25.335 | W3: 24.3 | X3: 25.517 | Y3: 24.166

Sheet Usinas Eolicas
A1: Beberibe | C1: 23:00 | D1: 0:00 | E1: 1:00 | F1: 2:00 | G1: 3:00 | H1: 4:00 | I1: 5:00 | J1: 6:00 | K1: 7:00 | L1: 8:00 | M1: 9:00 | N1: 10:00 | O1: 11:00 | P1: 12:00 | Q1: 13:00 | R1: 14:00 | S1: 15:00 | T1: 16:00 | U1: 17:00 | V1: 18:00 | W1: 19:00 | X1: 20:00 | Y1: 21:00 | Z1: 22:00
B2: Máximo | C2: 15 | D2: 12 | E2: 10.98 | F2: 11 | G2: 11 | H2: 10.95 | I2: 4.07 | J2: 3.98 | K2: 3 | L2: 3 | M2: 5 | N2: 5 | O2: 5 | P2: 7 | Q2: 8 | R2: 7.98 | S2: 6.92 | T2: 7 | U2: 7 | V2: 8 | W2: 7 | X2: 10 | Y2: 13 | Z2: 14
B3: Média | C3: 8.0495506 | D3: 6.7758239 | E3: 6.1168539 | F3: 6.5404944 | G3: 6.5483146 | H3: 4.7313483 | I3: 2.3868315 | J3: 1.777573 | K3: 1.7752809 | L3: 1.8337079 | M3: 3.0538652 | N3: 2.5067865 | O3: 3.0511236 | P3: 4.2200899 | Q3: 4.7730337 | R3: 4.224764 | S3: 3.6130562 | T3: 4.1606292 | U3: 4.2786517 | V3: 4.3370787 | W3: 4.2786517 | X3: 4.4539326 | Y3: 5.1819775 | Z3: 6.3416404
B4: Mínimo | C4: 0 | D4: 0 | E4: 0 | F4: 0 | G4: 0 | H4: 0 | I4: 0 | J4: 0 | K4: 0 | L4: 0 | M4: 0 | N4: 0 | O4: 0 | P4: 0 | Q4: 0 | R4: 0 | S4: 0 | T4: 0 | U4: 0 | V4: 0 | W4: 0 | X4: 0 | Y4: 0 | Z4: 0
A6: Boca do Córrego | C6: 23:00 | D6: 0:00 | E6: 1:00 | F6: 2:00 | G6: 3:00 | H6: 4:00 | I6: 5:00 | J6: 6:00 | K6: 7:00 | L6: 8:00 | M6: 9:00 | N6: 10:00 | O6: 11:00 | P6: 12:00 | Q6: 13:00 | R6: 14:00 | S6: 15:00 | T6: 16:00 | U6: 17:00 | V6: 18:00 | W6: 19:00 | X6: 20:00 | Y6: 21:00 | Z6: 22:00
B7: Máximo | C7: 22.061 | D7: 23.102 | E7: 22.635 | F7: 23.404 | G7: 22.919 | H7: 22.29 | I7: 23.86 | J7: 22.113 | K7: 22.577 | L7: 23.71 | M7: 23.097 | N7: 23.276 | O7: 23.407 | P7: 23.42 | Q7: 23.47 | R7: 23.49 | S7: 23.482 | T7: 23.546 | U7: 23.332 | V7: 23.101 | W7: 22.965 | X7: 23.25 | Y7: 22.19 | Z7: 22.824
B8: Média | C8: 6.628331 | D8: 6.2767235 | E8: 6.1332425 | F8: 6.0835905 | G8: 6.1207948 | H8: 5.8936509 | I8: 5.7774688 | J8: 5.4917525 | K8: 5.8542022 | L8: 8.0880433 | M8: 10.072262 | N8: 10.785099 | O8: 11.67126 | P8: 12.486568 | Q8: 13.120457 | R8: 13.324199 | S8: 13.326509 | T8: 12.855468 | U8: 11.380384 | V8: 9.5030322 | W8: 8.2130231 | X8: 7.5893702 | Y8: 7.1965704 | Z8: 6.8412696
B9: Mínimo | C9: 0 | D9: 0 | E9: 0 | F9: 0 | G9: 0 | H9: 0 | I9: 0 | J9: 0 | K9: 0 | L9: 0 | M9: 0 | N9: 0 | O9: 0 | P9: 0 | Q9: 0 | R9: 0 | S9: 0 | T9: 0 | U9: 0 | V9: 0 | W9: 0 | X9: 0 | Y9: 0 | Z9: 0
A11: Cataventos do Acaraú I | C11: 23:00 | D11: 0:00 | E11: 1:00 | F11: 2:00 | G11: 3:00 | H11: 4:00 | I11: 5:00 | J11: 6:00 | K11: 7:00 | L11: 8:00 | M11: 9:00 | N11: 10:00 | O11: 11:00 | P11: 12:00 | Q11: 13:00 | R11: 14:00 | S11: 15:00 | T11: 16:00 | U11: 17:00 | V11: 18:00 | W11: 19:00 | X11: 20:00 | Y11: 21:00 | Z11: 22:00
B12: Máximo | C12: 26.966 | D12: 26.469 | E12: 26.673 | F12: 26.493 | G12: 26.022 | H12: 25.647 | I12: 24.635 | J12: 24.011 | K12: 25.794 | L12: 26.577 | M12: 26.835 | N12: 26.937 | O12: 27.137 | P12: 27.12 | Q12: 27.16 | R12: 27.138 | S12: 27.128 | T12: 27.081 | U12: 27.067 | V12: 27.047 | W12: 26.813 | X12: 26.675 | Y12: 26.982 | Z12: 26.925
B13: Média | C13: 9.6120452 | D13: 8.9268312 | E13: 8.263594 | F13: 7.759338 | G13: 7.2398837 | H13: 6.6295976 | I13: 6.0449139 | J13: 5.3913759 | K13: 5.5471283 | L13: 7.2296602 | M13: 9.603362 | N13: 11.252799 | O13: 12.345655 | P13: 13.440292 | Q13: 14.3056 | R13: 14.820726 | S13: 15.088688 | T13: 15.016298 | U13: 14.474913 | V13: 13.533711 | W13: 12.548795 | X13: 11.764571 | Y13: 10.992259 | Z13: 10.246464
B14: Mínimo | C14: 0 | D14: 0 | E14: 0 | F14: 0 | G14: 0 | H14: 0 | I14: 0 | J14: 0 | K14: 0 | L14: 0 | M14: 0 | N14: 0 | O14: 0 | P14: 0 | Q14: 0 | R14: 0 | S14: 0 | T14: 0 | U14: 0 | V14: 0 | W14: 0 | X14: 0 | Y14: 0 | Z14: 0
A16: Colonia | C16: 23:00 | D16: 0:00 | E16: 1:00 | F16: 2:00 | G16: 3:00 | H16: 4:00 | I16: 5:00 | J16: 6:00 | K16: 7:00 | L16: 8:00 | M16: 9:00 | N16: 10:00 | O16: 11:00 | P16: 12:00 | Q16: 13:00 | R16: 14:00 | S16: 15:00 | T16: 16:00 | U16: 17:00 | V16: 18:00 | W16: 19:00 | X16: 20:00 | Y16: 21:00 | Z16: 22:00
B17: Máximo | C17: 18.644 | D17: 18.6 | E17: 18.594 | F17: 18.573 | G17: 18.505 | H17: 18.573 | I17: 18.347 | J17: 18.559 | K17: 18.17 | L17: 18.621 | M17: 18.847 | N17: 18.523 | O17: 18.911 | P17: 18.914 | Q17: 18.981 | R17: 18.582 | S17: 18.669 | T17: 18.655 | U17: 18.656 | V17: 18.7 | W17: 18.542 | X17: 18.475 | Y17: 18.541 | Z17: 18.77
B18: Média | C18: 11.044756 | D18: 10.911614 | E18: 10.616073 | F18: 10.127597 | G18: 9.400751 | H18: 8.7842402 | I18: 8.1357776 | J18: 7.5062633 | K18: 7.4321547 | L18: 8.4364599 | M18: 9.4471955 | N18: 10.416451 | O18: 11.492118 | P18: 12.223871 | Q18: 12.500686 | R18: 12.402933 | S18: 12.092376 | T18: 11.380085 | U18: 10.584018 | V18: 10.102103 | W18: 10.104276 | X18: 10.362304 | Y18: 10.698045 | Z18: 10.928321
B19: Mínimo | C19: 0 | D19: 0 | E19: 0 | F19: 0 | G19: 0 | H19: 0 | I19: 0 | J19: 0 | K19: 0 | L19: 0 | M19: 0 | N19: 0 | O19: 0 | P19: 0 | Q19: 0 | R19: 0 | S19: 0 | T19: 0 | U19: 0 | V19: 0 | W19: 0 | X19: 0 | Y19: 0 | Z19: 0
A21: Embuaca | C21: 23:00 | D21: 0:00 | E21: 1:00 | F21: 2:00 | G21: 3:00 | H21: 4:00 | I21: 5:00 | J21: 6:00 | K21: 7:00 | L21: 8:00 | M21: 9:00 | N21: 10:00 | O21: 11:00 | P21: 12:00 | Q21: 13:00 | R21: 14:00 | S21: 15:00 | T21: 16:00 | U21: 17:00 | V21: 18:00 | W21: 19:00 | X21: 20:00 | Y21: 21:00 | Z21: 22:00
B22: Máximo | C22: 24.228 | D22: 24.465 | E22: 24.166 | F22: 24.237 | G22: 24.166 | H22: 24.166 | I22: 24.166 | J22: 24.166 | K22: 24.216 | L22: 24.33 | M22: 24.717 | N22: 25.037 | O22: 24.99 | P22: 26.702 | Q22: 26.222 | R22: 26.914 | S22: 26.996 | T22: 26.505 | U22: 25.807 | V22: 24.455 | W22: 25.335 | X22: 24.3 | Y22: 25.517 | Z22: 24.166
B23: Média | C23: 8.9692379 | D23: 8.6749251 | E23: 8.4590865 | F23: 8.3679762 | G23: 8.0438344 | H23: 7.6759227 | I23: 7.3295064 | J23: 6.9134422 | K23: 7.3778252 | L23: 9.4617247 | M23: 11.071541 | N23: 11.915315 | O23: 12.70263 | P23: 13.472727 | Q23: 13.925987 | R23: 14.1263 | S23: 13.993348 | T23: 13.475853 | U23: 12.291004 | V23: 11.060175 | W23: 10.325209 | X23: 9.7525306 | Y23: 9.3808939 | Z23: 9.0806651
B24: Mínimo | C24: 0 | D24: 0 | E24: 0 | F24: 0 | G24: 0 | H24: 0 | I24: 0 | J24: 0 | K24: 0 | L24: 0 | M24: 0 | N24: 0 | O24: 0 | P24: 0 | Q24: 0 | R24: 0 | S24: 0 | T24: 0 | U24: 0 | V24: 0 | W24: 0 | X24: 0 | Y24: 0 | Z24: 0
