Workbook

Sheet Planilha1
A1: Time | B1: psolar
A2: 0.95833333 | B2: =Plot!B3 -> 0
A3: 0.96875 | B3: =B2+(($B$6-B2)/($A$6-A2)*(A2-A3)) -> 0
A4: 0.97916667 | B4: =B3+(($B$6-B3)/($A$6-A3)*(A3-A4)) -> 0
A5: 0.98958333 | B5: =B4+(($B$6-B4)/($A$6-A4)*(A4-A5)) -> 0
A6: 0 | B6: =Plot!C3 -> 0
A7: 0.010416667 | B7: =B6+(($B$10-B6)/($A$10-A6)*(A7-A6)) -> 0
A8: 0.020833333 | B8: =B7+(($B$10-B7)/($A$10-A7)*(A8-A7)) -> 0
A9: 0.03125 | B9: =B8+(($B$10-B8)/($A$10-A8)*(A9-A8)) -> 0
A10: 0.041666667 | B10: =Plot!D3 -> 0
A11: 0.052083333 | B11: =B10+((B10-$B$14)/(A10-$A$14))*(A11-A10) -> 0
A12: 0.0625 | B12: =B11+((B11-$B$14)/(A11-$A$14))*(A12-A11) -> 0
A13: 0.072916667 | B13: =B12+((B12-$B$14)/(A12-$A$14))*(A13-A12) -> 0
A14: 2:00 | B14: =Plot!E3 -> 0
A15: 0.09375 | B15: =B14+((B14-$B$18)/(A14-$A$18))*(A15-A14) -> 0
A16: 0.10416667 | B16: =B15+((B15-$B$18)/(A15-$A$18))*(A16-A15) -> 0
A17: 0.11458333 | B17: =B16+((B16-$B$18)/(A16-$A$18))*(A17-A16) -> 0
A18: 0.125 | B18: =Plot!F3 -> 0
A19: 0.13541667 | B19: =B18+((B18-$B$22)/(A18-$A$22))*(A19-A18) -> 0
A20: 0.14583333 | B20: =B19+((B19-$B$22)/(A19-$A$22))*(A20-A19) -> 0
A21: 0.15625 | B21: =B20+((B20-$B$22)/(A20-$A$22))*(A21-A20) -> 0
A22: 4:00 | B22: =Plot!G3 -> 0
A23: 0.17708333 | B23: =B22+((B22-$B$26)/(A22-$A$26))*(A23-A22) -> 0.61085301
A24: 0.1875 | B24: =B23+((B23-$B$26)/(A23-$A$26))*(A24-A23) -> 1.221706
A25: 0.19791667 | B25: =B24+((B24-$B$26)/(A24-$A$26))*(A25-A24) -> 1.832559
A26: 5:00 | B26: =Plot!H3 -> 2.4434121
A27: 0.21875 | B27: =B26+((B26-$B$30)/(A26-$A$30))*(A27-A26) -> 11.016652
A28: 0.22916667 | B28: =B27+((B27-$B$30)/(A27-$A$30))*(A28-A27) -> 19.589892
A29: 0.23958333 | B29: =B28+((B28-$B$30)/(A28-$A$30))*(A29-A28) -> 28.163132
A30: 6:00 | B30: =Plot!I3 -> 36.736372
A31: 0.26041667 | B31: =B30+((B30-$B$34)/(A30-$A$34))*(A31-A30) -> 44.200198
A32: 0.27083333 | B32: =B31+((B31-$B$34)/(A31-$A$34))*(A32-A31) -> 51.664023
A33: 0.28125 | B33: =B32+((B32-$B$34)/(A32-$A$34))*(A33-A32) -> 59.127849
A34: 7:00 | B34: =Plot!J3 -> 66.591674
A35: 0.30208333 | B35: =B34+((B34-$B$38)/(A34-$A$38))*(A35-A34) -> 69.544616
A36: 0.3125 | B36: =B35+((B35-$B$38)/(A35-$A$38))*(A36-A35) -> 72.497557
A37: 0.32291667 | B37: =B36+((B36-$B$38)/(A36-$A$38))*(A37-A36) -> 75.450499
A38: 8:00 | B38: =Plot!K3 -> 78.40344
A39: 0.34375 | B39: =B38+((B38-$B$42)/(A38-$A$42))*(A39-A38) -> 80.299325
A40: 0.35416667 | B40: =B39+((B39-$B$42)/(A39-$A$42))*(A40-A39) -> 82.19521
...

Sheet Plot
B2: 23:00 | C2: 0:00 | D2: 1:00 | E2: 2:00 | F2: 3:00 | G2: 4:00 | H2: 5:00 | I2: 6:00 | J2: 7:00 | K2: 8:00 | L2: 9:00 | M2: 10:00 | N2: 11:00 | O2: 12:00 | P2: 13:00 | Q2: 14:00 | R2: 15:00 | S2: 16:00 | T2: 17:00 | U2: 18:00 | V2: 19:00 | W2: 20:00 | X2: 21:00 | Y2: 22:00
A3: Sol do Futuro | B3: 0 | C3: 0 | D3: 0 | E3: 0 | F3: 0 | G3: 0 | H3: 2.4434121 | I3: 36.736372 | J3: 66.591674 | K3: 78.40344 | L3: 85.98698 | M3: 90.57446 | N3: 90.907835 | O3: 88.191356 | P3: 82.551942 | Q3: 72.206658 | R3: 58.730888 | S3: 33.66521 | T3: 3.6002235 | U3: 0.30525228 | V3: 0.13607358 | W3: 0.12797057 | X3: 0.06849124 | Y3: 0.035606868

Sheet Usinas Solar
A1: Alex | C1: 23:00 | D1: 0:00 | E1: 1:00 | F1: 2:00 | G1: 3:00 | H1: 4:00 | I1: 5:00 | J1: 6:00 | K1: 7:00 | L1: 8:00 | M1: 9:00 | N1: 10:00 | O1: 11:00 | P1: 12:00 | Q1: 13:00 | R1: 14:00 | S1: 15:00 | T1: 16:00 | U1: 17:00 | V1: 18:00 | W1: 19:00 | X1: 20:00 | Y1: 21:00 | Z1: 22:00
B2: Máximo | C2: 0 | D2: 0.008 | E2: 0.043 | F2: 0.034 | G2: 0.047 | H2: 0.426 | I2: 38.8 | J2: 224.05 | K2: 269.689 | L2: 274.616 | M2: 277.978 | N2: 278.251 | O2: 273.616 | P2: 273.339 | Q2: 272.743 | R2: 271.848 | S2: 257.358 | T2: 243.086 | U2: 243.086 | V2: 192.56 | W2: 5.018 | X2: 0 | Y2: 0 | Z2: 0
B3: Média | C3: 0 | D3: 2.173913e-05 | E3: 0.00011684783 | F3: 9.2391304e-05 | G3: 0.00012771739 | H3: 0.0014836957 | I3: 4.4836168 | J3: 83.751443 | K3: 172.57914 | L3: 203.61404 | M3: 211.70502 | N3: 214.8316 | O3: 212.03978 | P3: 205.66008 | Q3: 194.70924 | R3: 171.66698 | S3: 140.41744 | T3: 77.504065 | U3: 8.6583533 | V3: 0.67215217 | W3: 0.01363587 | X3: 0 | Y3: 0 | Z3: 0
B4: Mínimo | C4: 0 | D4: 0 | E4: 0 | F4: 0 | G4: 0 | H4: 0 | I4: 0 | J4: 0 | K4: 0 | L4: 0 | M4: 0 | N4: 0 | O4: 0 | P4: 0 | Q4: 0 | R4: 0 | S4: 0 | T4: 0 | U4: 0 | V4: 0 | W4: 0 | X4: 0 | Y4: 0 | Z4: 0
A6: Calcario | C6: 23:00 | D6: 0:00 | E6: 1:00 | F6: 2:00 | G6: 3:00 | H6: 4:00 | I6: 5:00 | J6: 6:00 | K6: 7:00 | L6: 8:00 | M6: 9:00 | N6: 10:00 | O6: 11:00 | P6: 12:00 | Q6: 13:00 | R6: 14:00 | S6: 15:00 | T6: 16:00 | U6: 17:00 | V6: 18:00 | W6: 19:00 | X6: 20:00 | Y6: 21:00 | Z6: 22:00
B7: Máximo | C7: 0 | D7: 0 | E7: 0 | F7: 0 | G7: 0 | H7: 0 | I7: 20.691 | J7: 95.107 | K7: 120.101 | L7: 123.283 | M7: 124.278 | N7: 125.746 | O7: 127.031 | P7: 127.621 | Q7: 127.154 | R7: 123.302 | S7: 116.189 | T7: 107.466 | U7: 97.737 | V7: 97.737 | W7: 97.737 | X7: 97.737 | Y7: 97.737 | Z7: 50.811
B8: Média | C8: 0 | D8: 0 | E8: 0 | F8: 0 | G8: 0 | H8: 0 | I8: 2.4434121 | J8: 36.736372 | K8: 66.591674 | L8: 78.40344 | M8: 85.98698 | N8: 90.57446 | O8: 90.907835 | P8: 88.191356 | Q8: 82.551942 | R8: 72.206658 | S8: 58.730888 | T8: 33.66521 | U8: 3.6002235 | V8: 0.30525228 | W8: 0.13607358 | X8: 0.12797057 | Y8: 0.06849124 | Z8: 0.035606868
B9: Mínimo | C9: 0 | D9: 0 | E9: 0 | F9: 0 | G9: 0 | H9: 0 | I9: 0 | J9: 0 | K9: 0 | L9: 0 | M9: 0 | N9: 0 | O9: 0 | P9: 0 | Q9: 0 | R9: 0 | S9: 0 | T9: 0 | U9: 0 | V9: 0 | W9: 0 | X9: 0 | Y9: 0 | Z9: 0
A11: Lavras | C11: 23:00 | D11: 0:00 | E11: 1:00 | F11: 2:00 | G11: 3:00 | H11: 4:00 | I11: 5:00 | J11: 6:00 | K11: 7:00 | L11: 8:00 | M11: 9:00 | N11: 10:00 | O11: 11:00 | P11: 12:00 | Q11: 13:00 | R11: 14:00 | S11: 15:00 | T11: 16:00 | U11: 17:00 | V11: 18:00 | W11: 19:00 | X11: 20:00 | Y11: 21:00 | Z11: 22:00
B12: Máximo | C12: 0.07 | D12: 0.07 | E12: 0.07 | F12: 0.07 | G12: 0.07 | H12: 0.07 | I12: 2.638 | J12: 64.001 | K12: 153.826 | L12: 180.674 | M12: 182 | N12: 179.471 | O12: 180.238 | P12: 180 | Q12: 177.546 | R12: 177.883 | S12: 171 | T12: 171 | U12: 65.72 | V12: 60 | W12: 11.31 | X12: 4.768 | Y12: 0.07 | Z12: 0.07
B13: Média | C13: 0.00071428571 | D13: 0.00071428571 | E13: 0.00071428571 | F13: 0.00071428571 | G13: 0.00071428571 | H13: 0.00071428571 | I13: 0.35989796 | J13: 24.334735 | K13: 74.125296 | L13: 100.17743 | M13: 108.43014 | N13: 110.39964 | O13: 112.65803 | P13: 111.64944 | Q13: 108.76319 | R13: 106.22329 | S13: 98.864163 | T13: 57.05499 | U13: 8.4773776 | V13: 1.0650612 | W13: 0.17513265 | X13: 0.049367347 | Y13: 0.00071428571 | Z13: 0.00071428571
B14: Mínimo | C14: 0 | D14: 0 | E14: 0 | F14: 0 | G14: 0 | H14: 0 | I14: 0 | J14: 0 | K14: 0 | L14: 0 | M14: 0 | N14: 0 | O14: 0 | P14: 0 | Q14: 0 | R14: 0 | S14: 0 | T14: 0 | U14: 0 | V14: 0 | W14: 0 | X14: 0 | Y14: 0 | Z14: 0
A16: Sol do Futuro | C16: 23:00 | D16: 0:00 | E16: 1:00 | F16: 2:00 | G16: 3:00 | H16: 4:00 | I16: 5:00 | J16: 6:00 | K16: 7:00 | L16: 8:00 | M16: 9:00 | N16: 10:00 | O16: 11:00 | P16: 12:00 | Q16: 13:00 | R16: 14:00 | S16: 15:00 | T16: 16:00 | U16: 17:00 | V16: 18:00 | W16: 19:00 | X16: 20:00 | Y16: 21:00 | Z16: 22:00
B17: Máximo | C17: 0.002 | D17: 0.604 | E17: 0.176 | F17: 0.278 | G17: 0.514 | H17: 0.044 | I17: 5.822 | J17: 34.592 | K17: 57.675 | L17: 63.052 | M17: 66.668 | N17: 67.115 | O17: 69.392 | P17: 68.929 | Q17: 67.336 | R17: 67.953 | S17: 61.983 | T17: 43.185 | U17: 40.575 | V17: 40.575 | W17: 40.575 | X17: 40.575 | Y17: 38.159 | Z17: 6.242
B18: Média | C18: 2.247191e-06 | D18: 0.00045393258 | E18: 0.00013333333 | F18: 0.00020973783 | G18: 0.00038651685 | H18: 3.4456929e-05 | I18: 0.48638352 | J18: 10.851663 | K18: 28.098638 | L18: 36.659514 | M18: 42.381699 | N18: 46.248543 | O18: 48.979487 | P18: 49.898072 | Q18: 49.883933 | R18: 47.331095 | S18: 40.173739 | T18: 19.333581 | U18: 1.1624824 | V18: 0.030393258 | W18: 0.030393258 | X18: 0.030393258 | Y18: 0.028586517 | Z18: 0.004682397
B19: Mínimo | C19: 0 | D19: 0 | E19: 0 | F19: 0 | G19: 0 | H19: 0 | I19: 0 | J19: 0 | K19: 0 | L19: 0 | M19: 0 | N19: 0 | O19: 0 | P19: 0 | Q19: 0 | R19: 0 | S19: 0 | T19: 0 | U19: 0 | V19: 0 | W19: 0 | X19: 0 | Y19: 0 | Z19: 0
